Workbook

Sheet 00_Data_Notes
A1: Random Blind-Box Full-Set Collection Strategy | Data Collection
A4: Field Type | B4: Color | C4: Meaning | E4: Collection Steps | F4: Main Worksheet | G4: Completion Flag
A5: Required | C5: Data essential for modeling | E5: 1. Select series and verify rules | F5: 01_Series_Basic_Info | G5: Confirm independent random draws, version, and character scope
A6: Conditionally Required | C6: Must fill in when the condition is met | E6: 2. Organize characters and probabilities | F6: 02_Character_Probabilities | G6: Probability sum passes check
A7: Optional | C7: Helps improve report quality but not a minimum requirement | E7: 3. Collect secondary-market prices and evidence | F7: 03_Secondary_Market_Raw_Data | G7: Each character reaches recommended sample size
A8: Auto-calculated | C8: Generated automatically by formula | E8: 4. Supplement transaction rules and self-check | F8: 04—06Worksheet | G8: Quality checklist has no major gaps
A10: Progress Metric | B10: Current Value | C10: Target | E10: Submission Checklist | F10: Completed?
A11: Number of target characters filled | B11: =COUNTIFS('02_Character_Probabilities'!B3:B10,"<>",'02_Character_Probabilities'!C3:C10,"Yes") -> 8 | C11: 6–12 | E11: Excel workbook fully completed | F11: Completed
A12: Number of secondary-market raw records | B12: =COUNTIF('03_Secondary_Market_Raw_Data'!A3:A299,"<>") -> 134 | C12: Preferably ≥15 per character | E12: Official info screenshots and links saved | F12: Completed
A13: Number of valid records included in analysis | B13: =COUNTIF('03_Secondary_Market_Raw_Data'!T3:T299,"Yes") -> 127 | C13: At least 8 per character is more reliable | E13: Secondary-market screenshots named by evidence ID | F13: Completed
A14: Valid records missing evidence ID | B14: =COUNTIFS('03_Secondary_Market_Raw_Data'!T3:T299,"Yes",'03_Secondary_Market_Raw_Data'!V3:V299,"") -> 0 | C14: 0 records | E14: Excluded data retained with reasons stated | F14: Completed
A15: Completed quality-check items | B15: =COUNTIF('06_Data_Quality_Check'!C3:C30,"Pass") -> 28 | C15: All required check items | E15: Folder named and packaged as required | F15: Completed

Sheet 01_Series_Basic_Info
A1: Series Basic Information and Official Rules
A2: Field Type | B2: Field Name | C2: Entry
A3: Required | B3: Full Series Name | C3: DEATH NOTE -My Dear Light- POP UP SHOP (Misa-themed exclusive pop-up / PARCO offline matte badge)
A4: Required | B4: Work / Title Name | C4: DEATH NOTE (デスノート / Death Note)
A5: Required | B5: Product Type | C5: Blind-box metal badge (トレーディング缶バッジ / Trading Badge)
A6: Required | B6: Product Specs / Size | C6: Diameter Φ56mm per badge; single independent blind bag; BOX contains 8 packs (8 badges)
A7: Required | B7: Release Batch / Version | C7: Batch1 Nagoya PARCO (2025.2.7–2.24); Batch2 Ikebukuro PARCO (2025.3.19–3.30); Batch3 Fukuoka PARCO (2025.5.23–6.8); Post restock (reservation 2026.4.3–5.10, ship June)
A8: Optional | B8: Official Release Date | C8: 2025-02-07
A9: Required | B9: Total Number of Target Characters n | C9: 8
A10: Required | B10: Official Random Unit Price | C10: 550 JPY (tax incl., single); BOX 4,400 JPY (tax incl.); China retail about 39.8 CNY
A11: Required | B11: Official Purchase Channels | C11: Offline: Nagoya/Ikebukuro/Fukuoka PARCO pop-up venues; Online restock: Sofmap ONLINE, PARCO ART official reservation
A12: Required | B12: Official Shipping Rules | C12: No shipping at offline venues; online restock shipping not clearly stated in public materials (subject to actual checkout)
A13: Optional | B13: Other Official Fees | C13: 0
A14: Required | B14: Items per Pack | C14: 1
A15: Required | B15: Independent Random per Pack? | C15: Yes
A16: Required | B16: Public Pity / Guarantee Mechanism? | C16: No pity for single packs (1 full BOX of 8 guarantees all 8 standard designs, no duplicates)
A17: Required | B17: Box Has No Duplicates / Fixed Box Ratio? | C17: Yes. Full box fixed set of 8 designs with no duplicates
A18: Required | B18: Hidden / Secret Designs? | C18: No. No hidden/SP/variant/foil designs; only 8 fixed original illustrations
A19: Conditionally Required | B19: Handling of Hidden Designs | C19: N/A (no hidden designs)
A20: Required | B20: Official Character Probabilities Published? | C20: Yes
A21: Conditionally Required | B21: Official Probability Description | C21: No rarity tiers; 8 designs equal factory ratio; BOX mechanism guarantees full set of 8
A22: Required | B22: Official Information Source URL | C22: 1.https://art.parco.jp/parcofactory/detail/?id=1701 2.https://prtimes.jp/main/html/rd/p/000003340.000003639.html 3.https://www.sofmap.com/product_detail_sp.aspx?sku=101920630 4.https://ikebukuro.parco.jp/
A23: Required | B23: Official Information Collection Date | C23: 1.PARCO ART:2025-01-22 (first)/2025-03-20 (recheck); 2.PR TIMES:2025-01-22; 3.Sofmap:2026-04-03/2026-04-15; 4.Ikebukuro PARCO:2025-03-18
A24: Required | B24: Official Evidence ID | C24: Sofmap SKU:101920630; PARCO FACTORY EVENT No.1701; Manufacturer: 株式会社アヴェンジャーズ
A25: Optional | B25: Reason for Choosing This Series | C25: Fixed 8 designs, no hidden; BOX guarantees full set no duplicates; independent random packs; complete official info; suitable for base blind-draw modeling and data collection
A26: Optional | B26: Other Remarks | C26: Finish: matte print, proportional single-character art, no glitter/relief. Purchase limit: max 1 BOX per person per checkout. Full set of 8: 1.Light Yagami front view 2.Light Yagami profile 3.L light-gray portrait 4.L dark-gray profile 5.Misa Amane smiling 6.Misa Amane choker 7.Near 8.Mello. All official pages archived via WebArchive.

Sheet 02_Character_Probabilities
A1: Character List and Draw Probabilities
A2: Character ID | B2: Character Name | C2: Target Character? | D2: Character Version / Design | E2: Official Probability | F2: Baseline Probability p_i | G2: Probability Setting Method | H2: Probability Source URL | I2: Low-Probability Scenario | J2: High-Probability Scenario | K2: Remarks | M2: Probability Check | N2: Result
A3: 1 | B3: Light Yagami, front view | C3: Yes | D3: front view | E3: Not published | F3: 0.125 | G3: Equal probability | H3: https://art.parco.jp/parcofactory/detail/?id=1701 | K3: Standard design | M3: Number of Target Characters | N3: =COUNTIF(C3:C10,"Yes") -> 8
A4: 2 | B4: Light Yagami, profile | C4: Yes | D4: profile | E4: Not published | F4: 0.125 | G4: Equal probability | H4: https://art.parco.jp/parcofactory/detail/?id=1701 | K4: Standard design | M4: Sum of Baseline Probabilities | N4: =SUM(F3:F10) -> 1
A5: 3 | B5: L, light-gray portrait | C5: Yes | D5: light-gray portrait | E5: Not published | F5: 0.125 | G5: Equal probability | H5: https://art.parco.jp/parcofactory/detail/?id=1701 | K5: Standard design | M5: Equals 1? | N5: =IF(ABS(N4-1)<0.0001,"Pass","Needs check") -> Pass
A6: 4 | B6: L, dark-gray profile | C6: Yes | D6: dark-gray profile | E6: Not published | F6: 0.125 | G6: Equal probability | H6: https://art.parco.jp/parcofactory/detail/?id=1701 | K6: Standard design | M6: Number of Missing Baseline Probabilities | N6: =COUNTIFS(C3:C10,"Yes",F3:F10,"") -> 0
A7: 5 | B7: Misa Amane, smiling | C7: Yes | D7: smiling | E7: Not published | F7: 0.125 | G7: Equal probability | H7: https://art.parco.jp/parcofactory/detail/?id=1701 | K7: Standard design
A8: 6 | B8: Misa Amane, choker | C8: Yes | D8: choker | E8: Not published | F8: 0.125 | G8: Equal probability | H8: https://art.parco.jp/parcofactory/detail/?id=1701 | K8: Standard design
A9: 7 | B9: Near | C9: Yes | D9: looking down, white paper | E9: Not published | F9: 0.125 | G9: Equal probability | H9: https://art.parco.jp/parcofactory/detail/?id=1701 | K9: Standard design
A10: 8 | B10: Mello | C10: Yes | D10: red-brown coat | E10: Not published | F10: 0.125 | G10: Equal probability | H10: https://art.parco.jp/parcofactory/detail/?id=1701 | K10: Standard design

Sheet 03_Secondary_Market_Raw_Data
A1: Secondary-Market Raw Records (one row per listing)
A2: Record ID | B2: Character Name | C2: Platform | D2: Product Title | E2: Product Link | F2: Collection Date | G2: Listing Price | H2: Free Shipping? | I2: Buyer Shipping Cost | J2: Platform Fees | K2: Actual Landed Cost | L2: Quantity | M2: Unit Converted Price | N2: Product Version | O2: Product Specs | P2: Condition | Q2: Sold as Single Character? | R2: Bundled? | S2: Abnormal Price? | T2: Include in Analysis? | U2: Exclusion Reason | V2: Evidence ID | W2: Screenshot File Name | X2: Remarks
A3: 1 | B3: Light Yagami, front view | C3: Xianyu | D3: 【【包邮出】死亡笔记 名古屋快闪 夜神月正脸徽章】 | E3: https://m.tb.cn/h.8hZ5v4h | F3: 46239 | G3: 45 | H3: Yes | I3: 0 | J3: 0 | K3: =IF(OR(G3="",G3=0),"",G3+IF(I3="",0,I3)+IF(J3="",0,J3)) -> 45 | L3: 1 | M3: =IF(OR(K3="",L3=0),"",K3/L3) -> 45 | N3: My Dear Light | O3: Φ56mm matte | P3: Opened, good condition | Q3: Yes | R3: No | S3: No | T3: Yes | V3: MKT-001 | W3: MKT-001.png
A4: 2 | B4: Light Yagami, front view | C4: Xianyu | D4: 【包邮出】死亡笔记名古屋快闪夜神月正脸】 | E4: https://m.tb.cn/h.8hZ6c8g | F4: 46239 | G4: 70 | H4: Yes | I4: 0 | J4: 0 | K4: =IF(OR(G4="",G4=0),"",G4+IF(I4="",0,I4)+IF(J4="",0,J4)) -> 70 | L4: 1 | M4: =IF(OR(K4="",L4=0),"",K4/L4) -> 70 | N4: My Dear Light | O4: Φ56mm matte | P4: Opened, good condition | Q4: Yes | R4: No | S4: No | T4: Yes | V4: MKT-002 | W4: MKT-002.png
A5: 3 | B5: Light Yagami, front view | C5: Xianyu | D5: 【出】死亡笔记 名古屋快闪吧唧 夜神月正脸】 | E5: https://m.tb.cn/h.85loirB | F5: 46239 | G5: 60 | H5: Yes | J5: 0 | K5: =IF(OR(G5="",G5=0),"",G5+IF(I5="",0,I5)+IF(J5="",0,J5)) -> 60 | L5: 1 | M5: =IF(OR(K5="",L5=0),"",K5/L5) -> 60 | N5: My Dear Light | O5: Φ56mm matte | P5: Sealed, new | Q5: Yes | R5: No | S5: No | T5: Yes | V5: MKT-003 | W5: MKT-003.png
A6: 4 | B6: Light Yagami, front view | C6: Xianyu | D6: 【标价非偏 不要直拍 先tt我 死亡笔记夜神月名古屋正脸吧唧】 | E6: https://m.tb.cn/h.8TobHp2 | F6: 46239 | G6: 44 | H6: Yes (excl. remote areas | J6: 0 | K6: =IF(OR(G6="",G6=0),"",G6+IF(I6="",0,I6)+IF(J6="",0,J6)) -> 44 | L6: 1 | M6: =IF(OR(K6="",L6=0),"",K6/L6) -> 44 | N6: My Dear Light | O6: Φ56mm matte | P6: Slight defect | Q6: Yes | R6: No | S6: No | T6: Yes | V6: MKT-004 | W6: MKT-004.png
A7: 5 | B7: Light Yagami, profile | C7: Xianyu | D7: 【夜神月侧脸吧唧 有原袋 保存良好】 | E7: https://m.tb.cn/h.85lSeVr | F7: 46239 | G7: 70 | H7: No | I7: 10 | J7: 0 | K7: =IF(OR(G7="",G7=0),"",G7+IF(I7="",0,I7)+IF(J7="",0,J7)) -> 80 | L7: 1 | M7: =IF(OR(K7="",L7=0),"",K7/L7) -> 80 | N7: My Dear Light | O7: Φ56mm matte | P7: Sealed, new | Q7: Yes | R7: No | S7: No | T7: Yes | V7: MKT-005 | W7: MKT-005.png
A8: 6 | B8: Light Yagami, profile | C8: Xianyu | D8: 【【出】死亡笔记DeathNote名古屋池袋快闪吧唧，夜神月侧】 | E8: https://m.tb.cn/h.85lSVae | F8: 46239 | G8: 68 | H8: No | I8: 12 | J8: 0 | K8: =IF(OR(G8="",G8=0),"",G8+IF(I8="",0,I8)+IF(J8="",0,J8)) -> 80 | L8: 1 | M8: =IF(OR(K8="",L8=0),"",K8/L8) -> 80 | N8: My Dear Light | O8: Φ56mm matte | P8: Sealed, new | Q8: Yes | R8: No | S8: No | T8: Yes | V8: MKT-006 | W8: MKT-006.png
A9: 7 | B9: Light Yagami, front view | C9: Xianyu | D9: 【出夜神月名古屋吧唧】【死亡笔记】 | E9: https://m.tb.cn/h.85ldtv8 | F9: 46239 | G9: 45.9 | H9: No | I9: 12 | J9: 0 | K9: =IF(OR(G9="",G9=0),"",G9+IF(I9="",0,I9)+IF(J9="",0,J9)) -> 57.9 | L9: 1 | M9: =IF(OR(K9="",L9=0),"",K9/L9) -> 57.9 | N9: My Dear Light | O9: Φ56mm matte | P9: Opened, good condition | Q9: Yes | R9: No | S9: No | T9: Yes | V9: MKT-007 | W9: MKT-007.png
A10: 8 | B10: Light Yagami, profile | C10: Xianyu | D10: 【【出】死亡笔记 My Dear Light快闪吧唧 夜神月】 | E10: https://m.tb.cn/h.8TMIVgE | F10: 46239 | G10: 58 | H10: Yes (excl. remote areas | I10: 0 | J10: 0 | K10: =IF(OR(G10="",G10=0),"",G10+IF(I10="",0,I10)+IF(J10="",0,J10)) -> 58 | L10: 1 | M10: =IF(OR(K10="",L10=0),"",K10/L10) -> 58 | N10: My Dear Light | O10: Φ56mm matte | P10: Condition unclear | Q10: Yes | R10: No | S10: No | T10: Yes | V10: MKT-008 | W10: MKT-008.png
A11: 9 | B11: Light Yagami, profile | C11: Xianyu | D11: 【【出】死亡笔记 My Dear Light快闪吧唧 夜神月】 | E11: https://m.tb.cn/h.8gPsqAk | F11: 46239 | G11: 67 | H11: No | I11: 12 | J11: 0 | K11: =IF(OR(G11="",G11=0),"",G11+IF(I11="",0,I11)+IF(J11="",0,J11)) -> 79 | L11: 1 | M11: =IF(OR(K11="",L11=0),"",K11/L11) -> 79 | N11: My Dear Light | O11: Φ56mm matte | P11: Slight defect | Q11: Yes | R11: No | S11: No | T11: Yes | V11: MKT-009 | W11: MKT-009.png
A12: 10 | B12: Light Yagami, profile | C12: Xianyu | D12: 【出国现】死亡笔记 名古屋快闪原画吧唧 夜神月 包邮】 | E12: https://m.tb.cn/h.8hZZTQq | F12: 46241 | G12: 50 | H12: Yes | I12: 0 | J12: 0 | K12: =IF(OR(G12="",G12=0),"",G12+IF(I12="",0,I12)+IF(J12="",0,J12)) -> 50 | L12: 1 | M12: =IF(OR(K12="",L12=0),"",K12/L12) -> 50 | N12: My Dear Light | O12: Φ56mm matte | P12: Opened, good condition | Q12: Yes | R12: No | S12: No | T12: Yes | V12: MKT-010 | W12: MKT-010.png
A13: 11 | B13: Light Yagami, profile | C13: Xianyu | D13: 【死亡笔记 名古屋快闪吧唧 夜神月】 | E13: https://m.tb.cn/h.8hZ0bn4 | F13: 46241 | G13: 56 | H13: Yes | I13: 0 | J13: 0 | K13: =IF(OR(G13="",G13=0),"",G13+IF(I13="",0,I13)+IF(J13="",0,J13)) -> 56 | L13: 1 | M13: =IF(OR(K13="",L13=0),"",K13/L13) -> 56 | N13: My Dear Light | O13: Φ56mm matte | P13: Opened, good condition | Q13: Yes | R13: No | S13: No | T13: Yes | V13: MKT-011 | W13: MKT-011.png
A14: 12 | B14: Light Yagami, front view | C14: Xianyu | D14: 【一位老员工。。直出50，不包邮】 | E14: https://m.tb.cn/h.8hZTPEH | F14: 46241 | G14: 50 | H14: No | I14: 10 | J14: 0 | K14: =IF(OR(G14="",G14=0),"",G14+IF(I14="",0,I14)+IF(J14="",0,J14)) -> 60 | L14: 1 | M14: =IF(OR(K14="",L14=0),"",K14/L14) -> 60 | N14: My Dear Light | O14: Φ56mm matte | P14: Slight defect | Q14: Yes | R14: No | S14: No | T14: Yes | V14: MKT-012 | W14: MKT-012.png
A15: 13 | B15: Light Yagami, front view | C15: Xianyu | D15: 【出夜神月名古屋吧唧 48包非偏】 | E15: https://m.tb.cn/h.8Toancr | F15: 46241 | G15: 48.29 | H15: Yes | I15: 0 | J15: 0 | K15: =IF(OR(G15="",G15=0),"",G15+IF(I15="",0,I15)+IF(J15="",0,J15)) -> 48.29 | L15: 1 | M15: =IF(OR(K15="",L15=0),"",K15/L15) -> 48.29 | N15: My Dear Light | O15: Φ56mm matte | P15: Condition not specified | Q15: Yes | R15: No | S15: No | T15: Yes | V15: MKT-013 | W15: MKT-013.png
A16: 14 | B16: Light Yagami, front view | C16: Xianyu | D16: 【【出】death note快闪夜神月吧唧】 | E16: https://m.tb.cn/h.8glbxOP | F16: 46241 | G16: 60 | H16: Yes | J16: 0 | K16: =IF(OR(G16="",G16=0),"",G16+IF(I16="",0,I16)+IF(J16="",0,J16)) -> 60 | L16: 1 | M16: =IF(OR(K16="",L16=0),"",K16/L16) -> 60 | N16: My Dear Light | O16: Φ56mm matte | P16: Sealed, new | Q16: Yes | R16: No | S16: No | T16: Yes | V16: MKT-014 | W16: MKT-014.png
A17: 15 | B17: Light Yagami, front view | C17: Xianyu | D17: 【【出】名古屋快闪死亡笔记】 | E17: https://m.tb.cn/h.8TobcaQ | F17: 46241 | G17: 63 | H17: Yes | J17: 0 | K17: =IF(OR(G17="",G17=0),"",G17+IF(I17="",0,I17)+IF(J17="",0,J17)) -> 63 | L17: 1 | M17: =IF(OR(K17="",L17=0),"",K17/L17) -> 63 | N17: My Dear Light | O17: Φ56mm matte | P17: Opened, good condition | Q17: Yes | R17: No | S17: No | T17: Yes | V17: MKT-015 | W17: MKT-015.png
A18: 16 | B18: Misa Amane, smiling | C18: Xianyu | D18: 【夜神月弥海砂吧唧，线下db产物，皆有原袋，不包官伤，两个70】 | E18: https://m.tb.cn/h.8hZl5VV | F18: 46241 | G18: 70 | H18: Yes | J18: 0 | K18: =IF(OR(G18="",G18=0),"",G18+IF(I18="",0,I18)+IF(J18="",0,J18)) -> 70 | L18: 2 | M18: =IF(OR(K18="",L18=0),"",K18/L18) -> 35 | N18: My Dear Light | O18: Φ56mm matte | P18: Opened, good condition | Q18: No | R18: Yes | S18: No | T18: No | U18: Bundled sale; unit price unclear | V18: MKT-016 | W18: MKT-016.png
A19: 17 | B19: L, dark-gray profile | C19: Xianyu | D19: 【死亡笔记L侧脸吧唧，名古屋快闪限定款】 | E19: https://m.tb.cn/h.8hZSrSv | F19: 46241 | G19: 64.4 | H19: Yes | J19: 0 | K19: =IF(OR(G19="",G19=0),"",G19+IF(I19="",0,I19)+IF(J19="",0,J19)) -> 64.4 | L19: 1 | M19: =IF(OR(K19="",L19=0),"",K19/L19) -> 64.4 | N19: My Dear Light | O19: Φ56mm matte | P19: Sealed, new | Q19: Yes | R19: No | S19: No | T19: Yes | V19: MKT-017 | W19: MKT-017.png
A20: 18 | B20: L, dark-gray profile | C20: Xianyu | D20: 【DNL侧脸吧唧】 | E20: https://m.tb.cn/h.8gl2SyE | F20: 46241 | G20: 60 | H20: No | I20: 6 | J20: 0 | K20: =IF(OR(G20="",G20=0),"",G20+IF(I20="",0,I20)+IF(J20="",0,J20)) -> 66 | L20: 1 | M20: =IF(OR(K20="",L20=0),"",K20/L20) -> 66 | N20: My Dear Light | O20: Φ56mm matte | P20: Opened, good condition | Q20: Yes | R20: No | S20: No | T20: Yes | V20: MKT-018 | W20: MKT-018.png
A21: 19 | B21: L, dark-gray profile | C21: Xianyu | D21: 【Death Note L侧脸吧唧 正版】 | E21: https://m.tb.cn/h.8To2L35 | F21: 46241 | G21: 45 | H21: Yes | J21: 0 | K21: =IF(OR(G21="",G21=0),"",G21+IF(I21="",0,I21)+IF(J21="",0,J21)) -> 45 | L21: 1 | M21: =IF(OR(K21="",L21=0),"",K21/L21) -> 45 | N21: My Dear Light | O21: Φ56mm matte | P21: Opened, good condition | Q21: Yes | R21: No | S21: No | T21: Yes | V21: MKT-019 | W21: MKT-019.png
A22: 20 | B22: L, light-gray portrait | C22: Xianyu | D22: 【DEATHNOTE DN名古屋快闪L吧唧】 | E22: https://m.tb.cn/h.8hawTxv | F22: 46241 | G22: 45 | H22: Yes | J22: 0 | K22: =IF(OR(G22="",G22=0),"",G22+IF(I22="",0,I22)+IF(J22="",0,J22)) -> 45 | L22: 1 | M22: =IF(OR(K22="",L22=0),"",K22/L22) -> 45 | N22: My Dear Light | O22: Φ56mm matte | P22: Opened, good condition | Q22: Yes | R22: No | S22: No | T22: Yes | V22: MKT-020 | W22: MKT-020.png
A23: 21 | B23: L, light-gray portrait | C23: Xianyu | D23: 【死亡笔记 L 名古屋吧唧】 | E23: https://m.tb.cn/h.7gPLTuJ | F23: 2026-08-07 | G23: 60 | H23: Yes | J23: 0 | K23: =IF(OR(G23="",G23=0),"",G23+IF(I23="",0,I23)+IF(J23="",0,J23)) -> 60 | L23: 1 | M23: =IF(OR(K23="",L23=0),"",K23/L23) -> 60 | N23: My Dear Light | O23: Φ56mm matte | P23: Opened, good condition | Q23: Yes | R23: No | S23: No | T23: Yes | V23: MKT-021 | W23: MKT-021.png
A24: 22 | B24: L, dark-gray profile | C24: Xianyu | D24: 【死亡笔记 L 名古屋吧唧】 | E24: https://m.tb.cn/h.8gPLTuJ | F24: 2026-08-08 | G24: 46 | H24: Yes | J24: 0 | K24: =IF(OR(G24="",G24=0),"",G24+IF(I24="",0,I24)+IF(J24="",0,J24)) -> 46 | L24: 1 | M24: =IF(OR(K24="",L24=0),"",K24/L24) -> 46 | N24: My Dear Light | O24: Φ56mm matte | P24: Sealed, new | Q24: Yes | R24: No | S24: No | T24: Yes | V24: MKT-022 | W24: MKT-022.png
A25: 23 | B25: L, light-gray portrait | C25: Xianyu | D25: 【全新L名古屋快闪吧唧，死亡笔记角色L，线下抽的，有原袋，保存】 | E25: https://m.tb.cn/h.8hawF47 | F25: 2026-08-08 | G25: 49 | H25: No | I25: 12 | J25: 0 | K25: =IF(OR(G25="",G25=0),"",G25+IF(I25="",0,I25)+IF(J25="",0,J25)) -> 61 | L25: 1 | M25: =IF(OR(K25="",L25=0),"",K25/L25) -> 61 | N25: My Dear Light | O25: Φ56mm matte | P25: Opened, good condition | Q25: Yes | R25: No | S25: No | T25: Yes | V25: MKT-023 | W25: MKT-023.png
A26: 24 | B26: L, light-gray portrait | C26: Xianyu | D26: 【死亡笔记L名古屋快闪吧唧】 | E26: https://m.tb.cn/h.8TMobzc | F26: 2026-08-08 | G26: 52 | H26: Yes | J26: 0 | K26: =IF(OR(G26="",G26=0),"",G26+IF(I26="",0,I26)+IF(J26="",0,J26)) -> 52 | L26: 1 | M26: =IF(OR(K26="",L26=0),"",K26/L26) -> 52 | N26: My Dear Light | O26: Φ56mm matte | P26: Opened, good condition | Q26: Yes | R26: No | S26: No | T26: Yes | V26: MKT-024 | W26: MKT-024.png
A27: 25 | B27: L, light-gray portrait | C27: Xianyu | D27: 【死亡笔记名古屋快闪吧唧L】 | E27: https://m.tb.cn/h.8TMokXh | F27: 2026-08-08 | G27: 76 | H27: Yes | J27: 0 | K27: =IF(OR(G27="",G27=0),"",G27+IF(I27="",0,I27)+IF(J27="",0,J27)) -> 76 | L27: 1 | M27: =IF(OR(K27="",L27=0),"",K27/L27) -> 76 | N27: My Dear Light | O27: Φ56mm matte | P27: Opened, good condition | Q27: Yes | R27: No | S27: No | T27: Yes | V27: MKT-025 | W27: MKT-025.png
A28: 26 | B28: L, light-gray portrait | C28: Xianyu | D28: 【【出】死亡笔记 deathnote 名古屋快闪原画磨砂吧唧 有原】 | E28: https://m.tb.cn/h.8haxvWj | F28: 2026-08-08 | G28: 55 | H28: No | I28: 6 | J28: 0 | K28: =IF(OR(G28="",G28=0),"",G28+IF(I28="",0,I28)+IF(J28="",0,J28)) -> 61 | L28: 1 | M28: =IF(OR(K28="",L28=0),"",K28/L28) -> 61 | N28: My Dear Light | O28: Φ56mm matte | P28: Opened, good condition | Q28: Yes | R28: No | S28: No | T28: Yes | V28: MKT-026 | W28: MKT-026.png
A29: 27 | B29: L, light-gray portrait | C29: Xianyu | D29: 【死亡笔记 名古屋快闪 池袋快闪 parco 吧唧】 | E29: https://m.tb.cn/h.8TMpM3x | F29: 2026-08-08 | G29: 45 | H29: Yes | J29: 0 | K29: =IF(OR(G29="",G29=0),"",G29+IF(I29="",0,I29)+IF(J29="",0,J29)) -> 45 | L29: 1 | M29: =IF(OR(K29="",L29=0),"",K29/L29) -> 45 | N29: My Dear Light | O29: Φ56mm matte | P29: Condition not specified | Q29: Yes | R29: No | S29: No | T29: Yes | V29: MKT-027 | W29: MKT-027.png
A30: 28 | B30: L, light-gray portrait | C30: Xianyu | D30: 【【出】死亡笔记deathnote名古屋快闪原画磨砂吧唧 有原】 | E30: https://m.tb.cn/h.85lUsxU | F30: 2026-08-08 | G30: 60 | H30: Yes | J30: 0 | K30: =IF(OR(G30="",G30=0),"",G30+IF(I30="",0,I30)+IF(J30="",0,J30)) -> 60 | L30: 1 | M30: =IF(OR(K30="",L30=0),"",K30/L30) -> 60 | N30: My Dear Light | O30: Φ56mm matte | P30: Opened, good condition | Q30: Yes | R30: No | S30: No | T30: Yes | V30: MKT-028 | W30: MKT-028.png
A31: 29 | B31: L, light-gray portrait | C31: Xianyu | D31: 【【出】死亡笔记池袋快闪吧唧 L】 | E31: https://m.tb.cn/h.85l5KPI | F31: 2026-08-08 | G31: 55 | H31: No | I31: 10 | J31: 0 | K31: =IF(OR(G31="",G31=0),"",G31+IF(I31="",0,I31)+IF(J31="",0,J31)) -> 65 | L31: 1 | M31: =IF(OR(K31="",L31=0),"",K31/L31) -> 65 | N31: My Dear Light | O31: Φ56mm matte | P31: Condition not specified | Q31: Yes | R31: No | S31: No | T31: Yes | V31: MKT-029 | W31: MKT-029.png
A32: 30 | B32: L, light-gray portrait | C32: Xianyu | D32: 【出死亡笔记L原画吧唧4个150r】 | E32: https://m.tb.cn/h.8glcWxM | F32: 2026-08-08 | G32: 150 | H32: No | I32: 5 | J32: 0 | K32: =IF(OR(G32="",G32=0),"",G32+IF(I32="",0,I32)+IF(J32="",0,J32)) -> 155 | L32: 4 | M32: =IF(OR(K32="",L32=0),"",K32/L32) -> 38.75 | N32: My Dear Light | O32: Φ56mm matte | P32: Condition not specified | Q32: No | R32: Yes | S32: No | T32: Yes | V32: MKT-030 | W32: MKT-030.png
A33: 31 | B33: Misa Amane, smiling | C33: Xianyu | D33: 【出 dn名古屋L，弥海砂，梅洛吧唧，都有原袋】 | E33: https://m.tb.cn/h.8To48w5 | F33: 2026-08-06 | G33: 40 | H33: No | I33: 12 | K33: =IF(OR(G33="",G33=0),"",G33+IF(I33="",0,I33)+IF(J33="",0,J33)) -> 52 | L33: 1 | M33: =IF(OR(K33="",L33=0),"",K33/L33) -> 52 | N33: My Dear Light | O33: Φ56mm matte | P33: Sealed, new / original bag | Q33: No | R33: Yes | S33: No | T33: Yes | V33: MKT-031 | W33: MKT-031.png
A34: 32 | B34: L, light-gray portrait | C34: Xianyu | D34: 【出 dn名古屋L，弥海砂，梅洛吧唧，都有原袋】 | E34: https://m.tb.cn/h.8To48w6 | F34: 2026-08-07 | G34: 60 | H34: No | I34: 12 | K34: =IF(OR(G34="",G34=0),"",G34+IF(I34="",0,I34)+IF(J34="",0,J34)) -> 72 | L34: 1 | M34: =IF(OR(K34="",L34=0),"",K34/L34) -> 72 | N34: My Dear Light | O34: Φ56mm matte | P34: Sealed, new / original bag | Q34: No | R34: Yes | S34: No | T34: Yes | V34: MKT-032 | W34: MKT-032.png
A35: 33 | B35: Mello | C35: Xianyu | D35: 【出 dn名古屋L，弥海砂，梅洛吧唧，都有原袋】 | E35: https://m.tb.cn/h.8To48w7 | F35: 2026-08-08 | G35: 30 | H35: No | I35: 12 | J35: 0 | K35: =IF(OR(G35="",G35=0),"",G35+IF(I35="",0,I35)+IF(J35="",0,J35)) -> 42 | L35: 1 | M35: =IF(OR(K35="",L35=0),"",K35/L35) -> 42 | N35: My Dear Light | O35: Φ56mm matte | P35: Sealed, new / original bag | Q35: No | R35: Yes | S35: No | T35: No | U35: Bundled sale; unit price unclear | V35: MKT-033 | W35: MKT-033.png
A36: 34 | B36: Misa Amane, choker | C36: Xianyu | D36: 【死亡笔记 弥海砂名古屋快闪原画吧唧，全新未拆，有原包装。日版】 | E36: https://m.tb.cn/h.85lka0J | F36: 2026-08-08 | G36: 35 | H36: Yes | J36: 0 | K36: =IF(OR(G36="",G36=0),"",G36+IF(I36="",0,I36)+IF(J36="",0,J36)) -> 35 | L36: 1 | M36: =IF(OR(K36="",L36=0),"",K36/L36) -> 35 | N36: My Dear Light | O36: Φ56mm matte | P36: Sealed, new / original bag | Q36: Yes | R36: No | S36: No | T36: Yes | V36: MKT-034 | W36: MKT-034.png
A37: 35 | B37: Misa Amane, choker | C37: Xianyu | D37: 【弥海砂名古屋快闪吧唧 总共标价11个】 | E37: https://m.tb.cn/h.8hZelaw | F37: 2026-08-08 | J37: 0 | K37: =IF(OR(G37="",G37=0),"",G37+IF(I37="",0,I37)+IF(J37="",0,J37)) | L37: 1 | M37: =IF(OR(K37="",L37=0),"",K37/L37) | N37: My Dear Light | O37: Φ56mm matte | P37: Condition not specified | Q37: Yes | R37: No | S37: No | T37: Yes | V37: MKT-035 | W37: MKT-035.png
A38: 36 | B38: Misa Amane, choker | C38: Xianyu | D38: 【死亡笔记弥海砂吧唧】 | E38: https://m.tb.cn/h.8TMC7lv | F38: 2026-08-08 | G38: 50 | H38: No | I38: 10 | J38: 0 | K38: =IF(OR(G38="",G38=0),"",G38+IF(I38="",0,I38)+IF(J38="",0,J38)) -> 60 | L38: 1 | M38: =IF(OR(K38="",L38=0),"",K38/L38) -> 60 | N38: My Dear Light | O38: Φ56mm matte | P38: Opened, good condition | Q38: Yes | R38: No | S38: No | T38: Yes | V38: MKT-036 | W38: MKT-036.png
A39: 37 | B39: Misa Amane, smiling | C39: Xianyu | D39: 【出】deathnote死亡笔记，弥海砂misa名古屋吧唧】 | E39: https://m.tb.cn/h.85lrZ1E | F39: 2026-08-08 | G39: 35 | H39: Yes | J39: 0 | K39: =IF(OR(G39="",G39=0),"",G39+IF(I39="",0,I39)+IF(J39="",0,J39)) -> 35 | L39: 1 | M39: =IF(OR(K39="",L39=0),"",K39/L39) -> 35 | N39: My Dear Light | O39: Φ56mm matte | P39: Opened, good condition | Q39: Yes | R39: No | S39: No | T39: Yes | V39: MKT-037 | W39: MKT-037.png
A40: 38 | B40: Misa Amane, smiling | C40: Xianyu | D40: 【出 死亡笔记 dn名古屋弥海砂吧唧】 | E40: https://m.tb.cn/h.8To3Rip | F40: 2026-08-08 | G40: 35.12 | H40: No | I40: 10 | J40: 0 | K40: =IF(OR(G40="",G40=0),"",G40+IF(I40="",0,I40)+IF(J40="",0,J40)) -> 45.12 | L40: 1 | M40: =IF(OR(K40="",L40=0),"",K40/L40) -> 45.12 | N40: My Dear Light | O40: Φ56mm matte | P40: Opened, good condition | Q40: Yes | R40: No | S40: No | T40: Yes | V40: MKT-038 | W40: MKT-038.png
...

Sheet 04_Duplicate_Resale
A1: Duplicate Resale Data
A2: Character Name | B2: Resale Listing Price | C2: Expected Transaction Discount | D2: Expected Transaction Price | E2: Platform Commission Rate | F2: Seller-Paid Shipping | G2: Packaging Material Cost | H2: Net Income per Sale | I2: Expected Sale Probability λ_i | J2: Baseline Net Recovery Value r_i
A3: Required | B3: Conditionally Required | C3: Optional | D3: Auto-calculated | E3: Conditionally Required | F3: Conditionally Required | G3: Optional | H3: Auto-calculated | I3: Optional | J3: Auto-calculated
A4: Light Yagami, front view | B4: 60 | D4: =IF(A4="","",B4*IF(C4="",1,C4)) -> 60 | E4: 0.006 | F4: 6 | G4: 4 | H4: =IF(A4="","",MAX((D4-F4)*(1-E4)-G4,0)) -> 49.676 | I4: 0.6 | J4: =IF(A4="","",H4*IF(I4="",1,I4)) -> 29.8056
A5: Light Yagami, profile | B5: 58 | D5: =IF(A5="","",B5*IF(C5="",1,C5)) -> 58 | E5: 0.006 | F5: 6 | G5: 4 | H5: =IF(A5="","",MAX(D5*(1-E5)-F5-G5,0)) -> 47.652 | I5: 0.6 | J5: =IF(A5="","",H5*IF(I5="",1,I5)) -> 28.5912
A6: L, light-gray portrait | B6: 60 | D6: =IF(A6="","",B6*IF(C6="",1,C6)) -> 60 | E6: 0.006 | F6: 6 | G6: 4 | H6: =IF(A6="","",MAX(D6*(1-E6)-F6-G6,0)) -> 49.64 | I6: 0.6 | J6: =IF(A6="","",H6*IF(I6="",1,I6)) -> 29.784
A7: L, dark-gray profile | B7: 58.5 | D7: =IF(A7="","",B7*IF(C7="",1,C7)) -> 58.5 | E7: 0.006 | F7: 6 | G7: 4 | H7: =IF(A7="","",MAX(D7*(1-E7)-F7-G7,0)) -> 48.149 | I7: 0.6 | J7: =IF(A7="","",H7*IF(I7="",1,I7)) -> 28.8894
A8: Misa Amane, smiling | B8: 37.75 | D8: =IF(A8="","",B8*IF(C8="",1,C8)) -> 37.75 | E8: 0.006 | F8: 6 | G8: 4 | H8: =IF(A8="","",MAX(D8*(1-E8)-F8-G8,0)) -> 27.5235 | I8: 0.6 | J8: =IF(A8="","",H8*IF(I8="",1,I8)) -> 16.5141
A9: Misa Amane, choker | B9: 32 | D9: =IF(A9="","",B9*IF(C9="",1,C9)) -> 32 | E9: 0.006 | F9: 6 | G9: 4 | H9: =IF(A9="","",MAX(D9*(1-E9)-F9-G9,0)) -> 21.808 | I9: 0.6 | J9: =IF(A9="","",H9*IF(I9="",1,I9)) -> 13.0848
A10: Near | B10: 20.33 | D10: =IF(A10="","",B10*IF(C10="",1,C10)) -> 20.33 | E10: 0.006 | F10: 6 | G10: 4 | H10: =IF(A10="","",MAX(D10*(1-E10)-F10-G10,0)) -> 10.20802 | I10: 0.6 | J10: =IF(A10="","",H10*IF(I10="",1,I10)) -> 6.124812
A11: Mello | B11: 40 | D11: =IF(A11="","",B11*IF(C11="",1,C11)) -> 40 | E11: 0.006 | F11: 6 | G11: 4 | H11: =IF(A11="","",MAX(D11*(1-E11)-F11-G11,0)) -> 29.76 | I11: 0.6 | J11: =IF(A11="","",H11*IF(I11="",1,I11)) -> 17.856
D12: =IF(A12="","",B12*IF(C12="",1,C12)) | H12: =IF(A12="","",MAX(D12*(1-E12)-F12-G12,0)) | J12: =IF(A12="","",H12*IF(I12="",1,I12))
D13: =IF(A13="","",B13*IF(C13="",1,C13)) | H13: =IF(A13="","",MAX(D13*(1-E13)-F13-G13,0)) | J13: =IF(A13="","",H13*IF(I13="",1,I13))
D14: =IF(A14="","",B14*IF(C14="",1,C14)) | H14: =IF(A14="","",MAX(D14*(1-E14)-F14-G14,0)) | J14: =IF(A14="","",H14*IF(I14="",1,I14))
D15: =IF(A15="","",B15*IF(C15="",1,C15)) | H15: =IF(A15="","",MAX(D15*(1-E15)-F15-G15,0)) | J15: =IF(A15="","",H15*IF(I15="",1,I15))

Sheet 05_Shipping_Transaction_Rules
A1: Shipping and Transaction Rules
A2: Field Type | B2: Rule Item | C2: Entry
A3: Required | B3: Official Per-Order Shipping | C3: Offline venue 0; online restock not specified
A4: Conditionally Required | B4: Official Bulk-Purchase Shipping | C4: Offline venue 0
A5: Optional | B5: Official Free-Shipping Threshold | C5: No shipping offline; online not specified
A6: Required | B6: Common Buyer Shipping in Secondary Market | C6: Xianyu typically 6–12 CNY or free shipping
A7: Optional | B7: Free-Shipping Ratio in Secondary Records | C7: About 56.9%
A8: Required | B8: Can Missing Characters Be Bought Together? | C8: Yes
A9: Conditionally Required | B9: One-Time Shipping for Combined Purchase
A10: Optional | B10: Buyer Platform Fees | C10: 0
A11: Conditionally Required | B11: Seller Platform Commission Rate | C11: Xianyu about 0.6%–1%;
A12: Conditionally Required | B12: Who Pays Resale Shipping | C12: Seller
A13: Optional | B13: Packaging Material Cost
A14: Required | B14: Baseline Shipping Scenario | C14: Shipping charged per secondary-market order
A15: Optional | B15: Low-Shipping Scenario | C15: All free shipping
A16: Optional | B16: High-Shipping Scenario | C16: Add 12 CNY per character
A17: Required | B17: Transaction Rules Source URL | C17: Xianyu platform rules and sample observation
A18: Required | B18: Transaction Rules Evidence ID

Sheet 06_Data_Quality_Check
A1: Data Quality Checklist
A2: Category | B2: Check Item | C2: Status
A3: Research Object | B3: All records belong to the same series | C3: Pass
A4: Research Object | B4: All records same product type and specs | C4: Pass
A5: Research Object | B5: All records same release batch/version | C5: Pass
A6: Sales Mechanism | B6: Confirmed independent random per pack | C6: Pass
A7: Sales Mechanism | B7: Verified pity, no-duplicate box, and fixed box ratio | C7: Pass
A8: Character Scope | B8: Target character list complete with clear boundaries | C8: Pass
A9: Probability | B9: All target character probabilities are positive | C9: Pass
A10: Probability | B10: Sum of baseline probabilities equals 1 | C10: Pass
A11: Probability | B11: Equal-probability basis stated when no official probs | C11: Pass
A12: Sampling | B12: Same sampling time window for all characters | C12: Pass
A13: Sampling | B13: Same sampling rules for all characters | C13: Pass
... A30: Submission | B30: File naming and folder structure meet requirements | C30: Pass

Sheet 07_Collection_Progress_Summary
A1: Secondary-Market Data Collection Progress by Character
A2: Character ID | B2: Character Name | C2: Raw Record Count | D2: Valid Record Count | E2: Valid Records Missing Evidence | F2: Sample Assessment
A3: =IF('02_Character_Probabilities'!B3="","",'02_Character_Probabilities'!A3) -> 1 | B3: =IF('02_Character_Probabilities'!B3="","",'02_Character_Probabilities'!B3) -> Light Yagami, front view | C3: =IF(B3="","",COUNTIF('03_Secondary_Market_Raw_Data'!B$3:B$299,B3)) -> 18 | D3: =IF(B3="","",COUNTIFS('03_Secondary_Market_Raw_Data'!B$3:B$299,B3,'03_Secondary_Market_Raw_Data'!T$3:T$299,"Yes")) -> 16 | E3: =IF(B3="","",COUNTIFS('03_Secondary_Market_Raw_Data'!B$3:B$299,B3,'03_Secondary_Market_Raw_Data'!T$3:T$299,"Yes",'03_Secondary_Market_Raw_Data'!V$3:V$299,"")) -> 0 | F3: =IF(B3="","Not started",IF(D3>=15,"Satisfactory",IF(D3>=8,"Basically usable",IF(D3>=5,"Weak",IF(D3>0,"Insufficient","Not started"))))) -> Satisfactory
A4: =IF('02_Character_Probabilities'!B4="","",'02_Character_Probabilities'!A4) -> 2 | B4: =IF('02_Character_Probabilities'!B4="","",'02_Character_Probabilities'!B4) -> Light Yagami, profile | C4: =IF(B4="","",COUNTIF('03_Secondary_Market_Raw_Data'!B$3:B$299,B4)) -> 17 | D4: =IF(B4="","",COUNTIFS('03_Secondary_Market_Raw_Data'!B$3:B$299,B4,'03_Secondary_Market_Raw_Data'!T$3:T$299,"Yes")) -> 17 | E4: =IF(B4="","",COUNTIFS('03_Secondary_Market_Raw_Data'!B$3:B$299,B4,'03_Secondary_Market_Raw_Data'!T$3:T$299,"Yes",'03_Secondary_Market_Raw_Data'!V$3:V$299,"")) -> 0 | F4: =IF(B4="","Not started",IF(D4>=15,"Satisfactory",IF(D4>=8,"Basically usable",IF(D4>=5,"Weak",IF(D4>0,"Insufficient","Not started"))))) -> Satisfactory
A5: =IF('02_Character_Probabilities'!B5="","",'02_Character_Probabilities'!A5) -> 3 | B5: =IF('02_Character_Probabilities'!B5="","",'02_Character_Probabilities'!B5) -> L, light-gray portrait | C5: =IF(B5="","",COUNTIF('03_Secondary_Market_Raw_Data'!B$3:B$299,B5)) -> 20 | D5: =IF(B5="","",COUNTIFS('03_Secondary_Market_Raw_Data'!B$3:B$299,B5,'03_Secondary_Market_Raw_Data'!T$3:T$299,"Yes")) -> 20 | E5: =IF(B5="","",COUNTIFS('03_Secondary_Market_Raw_Data'!B$3:B$299,B5,'03_Secondary_Market_Raw_Data'!T$3:T$299,"Yes",'03_Secondary_Market_Raw_Data'!V$3:V$299,"")) -> 0 | F5: =IF(B5="","Not started",IF(D5>=15,"Satisfactory",IF(D5>=8,"Basically usable",IF(D5>=5,"Weak",IF(D5>0,"Insufficient","Not started"))))) -> Satisfactory
A6: =IF('02_Character_Probabilities'!B6="","",'02_Character_Probabilities'!A6) -> 4 | B6: =IF('02_Character_Probabilities'!B6="","",'02_Character_Probabilities'!B6) -> L, dark-gray profile | C6: =IF(B6="","",COUNTIF('03_Secondary_Market_Raw_Data'!B$3:B$299,B6)) -> 14 | D6: =IF(B6="","",COUNTIFS('03_Secondary_Market_Raw_Data'!B$3:B$299,B6,'03_Secondary_Market_Raw_Data'!T$3:T$299,"Yes")) -> 14 | E6: =IF(B6="","",COUNTIFS('03_Secondary_Market_Raw_Data'!B$3:B$299,B6,'03_Secondary_Market_Raw_Data'!T$3:T$299,"Yes",'03_Secondary_Market_Raw_Data'!V$3:V$299,"")) -> 0 | F6: =IF(B6="","Not started",IF(D6>=15,"Satisfactory",IF(D6>=8,"Basically usable",IF(D6>=5,"Weak",IF(D6>0,"Insufficient","Not started"))))) -> Basically usable
A7: =IF('02_Character_Probabilities'!B7="","",'02_Character_Probabilities'!A7) -> 5 | B7: =IF('02_Character_Probabilities'!B7="","",'02_Character_Probabilities'!B7) -> Misa Amane, smiling | C7: =IF(B7="","",COUNTIF('03_Secondary_Market_Raw_Data'!B$3:B$299,B7)) -> 16 | D7: =IF(B7="","",COUNTIFS('03_Secondary_Market_Raw_Data'!B$3:B$299,B7,'03_Secondary_Market_Raw_Data'!T$3:T$299,"Yes")) -> 14 | E7: =IF(B7="","",COUNTIFS('03_Secondary_Market_Raw_Data'!B$3:B$299,B7,'03_Secondary_Market_Raw_Data'!T$3:T$299,"Yes",'03_Secondary_Market_Raw_Data'!V$3:V$299,"")) -> 0 | F7: =IF(B7="","Not started",IF(D7>=15,"Satisfactory",IF(D7>=8,"Basically usable",IF(D7>=5,"Weak",IF(D7>0,"Insufficient","Not started"))))) -> Basically usable
A8: =IF('02_Character_Probabilities'!B8="","",'02_Character_Probabilities'!A8) -> 6 | B8: =IF('02_Character_Probabilities'!B8="","",'02_Character_Probabilities'!B8) -> Misa Amane, choker | C8: =IF(B8="","",COUNTIF('03_Secondary_Market_Raw_Data'!B$3:B$299,B8)) -> 15 | D8: =IF(B8="","",COUNTIFS('03_Secondary_Market_Raw_Data'!B$3:B$299,B8,'03_Secondary_Market_Raw_Data'!T$3:T$299,"Yes")) -> 15 | E8: =IF(B8="","",COUNTIFS('03_Secondary_Market_Raw_Data'!B$3:B$299,B8,'03_Secondary_Market_Raw_Data'!T$3:T$299,"Yes",'03_Secondary_Market_Raw_Data'!V$3:V$299,"")) -> 0 | F8: =IF(B8="","Not started",IF(D8>=15,"Satisfactory",IF(D8>=8,"Basically usable",IF(D8>=5,"Weak",IF(D8>0,"Insufficient","Not started"))))) -> Satisfactory
A9: =IF('02_Character_Probabilities'!B9="","",'02_Character_Probabilities'!A9) -> 7 | B9: =IF('02_Character_Probabilities'!B9="","",'02_Character_Probabilities'!B9) -> Near | C9: =IF(B9="","",COUNTIF('03_Secondary_Market_Raw_Data'!B$3:B$299,B9)) -> 18 | D9: =IF(B9="","",COUNTIFS('03_Secondary_Market_Raw_Data'!B$3:B$299,B9,'03_Secondary_Market_Raw_Data'!T$3:T$299,"Yes")) -> 17 | E9: =IF(B9="","",COUNTIFS('03_Secondary_Market_Raw_Data'!B$3:B$299,B9,'03_Secondary_Market_Raw_Data'!T$3:T$299,"Yes",'03_Secondary_Market_Raw_Data'!V$3:V$299,"")) -> 0 | F9: =IF(B9="","Not started",IF(D9>=15,"Satisfactory",IF(D9>=8,"Basically usable",IF(D9>=5,"Weak",IF(D9>0,"Insufficient","Not started"))))) -> Satisfactory
A10: =IF('02_Character_Probabilities'!B10="","",'02_Character_Probabilities'!A10) -> 8 | B10: =IF('02_Character_Probabilities'!B10="","",'02_Character_Probabilities'!B10) -> Mello | C10: =IF(B10="","",COUNTIF('03_Secondary_Market_Raw_Data'!B$3:B$299,B10)) -> 16 | D10: =IF(B10="","",COUNTIFS('03_Secondary_Market_Raw_Data'!B$3:B$299,B10,'03_Secondary_Market_Raw_Data'!T$3:T$299,"Yes")) -> 14 | E10: =IF(B10="","",COUNTIFS('03_Secondary_Market_Raw_Data'!B$3:B$299,B10,'03_Secondary_Market_Raw_Data'!T$3:T$299,"Yes",'03_Secondary_Market_Raw_Data'!V$3:V$299,"")) -> 0 | F10: =IF(B10="","Not started",IF(D10>=15,"Satisfactory",IF(D10>=8,"Basically usable",IF(D10>=5,"Weak",IF(D10>0,"Insufficient","Not started"))))) -> Basically usable
A11: =IF('02_Character_Probabilities'!#REF!="","",'02_Character_Probabilities'!#REF!) -> #REF! | B11: =IF('02_Character_Probabilities'!#REF!="","",'02_Character_Probabilities'!#REF!) -> #REF! | C11: =IF(B11="","",COUNTIF('03_Secondary_Market_Raw_Data'!B$3:B$299,B11)) -> #REF! | D11: =IF(B11="","",COUNTIFS('03_Secondary_Market_Raw_Data'!B$3:B$299,B11,'03_Secondary_Market_Raw_Data'!T$3:T$299,"Yes")) -> #REF! | E11: =IF(B11="","",COUNTIFS('03_Secondary_Market_Raw_Data'!B$3:B$299,B11,'03_Secondary_Market_Raw_Data'!T$3:T$299,"Yes",'03_Secondary_Market_Raw_Data'!V$3:V$299,"")) -> #REF! | F11: =IF(B11="","Not started",IF(D11>=15,"Satisfactory",IF(D11>=8,"Basically usable",IF(D11>=5,"Weak",IF(D11>0,"Insufficient","Not started"))))) -> #REF!
A12: =IF('02_Character_Probabilities'!#REF!="","",'02_Character_Probabilities'!#REF!) -> #REF! | B12: =IF('02_Character_Probabilities'!#REF!="","",'02_Character_Probabilities'!#REF!) -> #REF! | C12: =IF(B12="","",COUNTIF('03_Secondary_Market_Raw_Data'!B$3:B$299,B12)) -> #REF! | D12: =IF(B12="","",COUNTIFS('03_Secondary_Market_Raw_Data'!B$3:B$299,B12,'03_Secondary_Market_Raw_Data'!T$3:T$299,"Yes")) -> #REF! | E12: =IF(B12="","",COUNTIFS('03_Secondary_Market_Raw_Data'!B$3:B$299,B12,'03_Secondary_Market_Raw_Data'!T$3:T$299,"Yes",'03_Secondary_Market_Raw_Data'!V$3:V$299,"")) -> #REF! | F12: =IF(B12="","Not started",IF(D12>=15,"Satisfactory",IF(D12>=8,"Basically usable",IF(D12>=5,"Weak",IF(D12>0,"Insufficient","Not started"))))) -> #REF!
A13: =IF('02_Character_Probabilities'!#REF!="","",'02_Character_Probabilities'!#REF!) -> #REF! | B13: =IF('02_Character_Probabilities'!#REF!="","",'02_Character_Probabilities'!#REF!) -> #REF! | C13: =IF(B13="","",COUNTIF('03_Secondary_Market_Raw_Data'!B$3:B$299,B13)) -> #REF! | D13: =IF(B13="","",COUNTIFS('03_Secondary_Market_Raw_Data'!B$3:B$299,B13,'03_Secondary_Market_Raw_Data'!T$3:T$299,"Yes")) -> #REF! | E13: =IF(B13="","",COUNTIFS('03_Secondary_Market_Raw_Data'!B$3:B$299,B13,'03_Secondary_Market_Raw_Data'!T$3:T$299,"Yes",'03_Secondary_Market_Raw_Data'!V$3:V$299,"")) -> #REF! | F13: =IF(B13="","Not started",IF(D13>=15,"Satisfactory",IF(D13>=8,"Basically usable",IF(D13>=5,"Weak",IF(D13>0,"Insufficient","Not started"))))) -> #REF!
A14: =IF('02_Character_Probabilities'!#REF!="","",'02_Character_Probabilities'!#REF!) -> #REF! | B14: =IF('02_Character_Probabilities'!#REF!="","",'02_Character_Probabilities'!#REF!) -> #REF! | C14: =IF(B14="","",COUNTIF('03_Secondary_Market_Raw_Data'!B$3:B$299,B14)) -> #REF! | D14: =IF(B14="","",COUNTIFS('03_Secondary_Market_Raw_Data'!B$3:B$299,B14,'03_Secondary_Market_Raw_Data'!T$3:T$299,"Yes")) -> #REF! | E14: =IF(B14="","",COUNTIFS('03_Secondary_Market_Raw_Data'!B$3:B$299,B14,'03_Secondary_Market_Raw_Data'!T$3:T$299,"Yes",'03_Secondary_Market_Raw_Data'!V$3:V$299,"")) -> #REF! | F14: =IF(B14="","Not started",IF(D14>=15,"Satisfactory",IF(D14>=8,"Basically usable",IF(D14>=5,"Weak",IF(D14>0,"Insufficient","Not started"))))) -> #REF!

Sheet 08_Data_Dictionary
A1: Data Dictionary: Field Definitions, Formats, and Examples
A2: Worksheet | B2: Field Name | C2: Field Type | D2: Definition | E2: Entry Format | F2: Allowed Values / Rules
A3: 01_Series_Basic_Info | B3: Full Series Name | C3: Required | D3: Use the full name from the official page | E3: Text / numeric / date | F3: Fill as instructed
A4: 01_Series_Basic_Info | B4: Work / Title Name | C4: Required | D4: Related anime, game, or film/TV work | E4: Text / numeric / date | F4: Fill as instructed
A5: 01_Series_Basic_Info | B5: Product Type | C5: Required | D5: Badge, card, standee, etc. | E5: Text / numeric / date | F5: Fill as instructed
A6: 01_Series_Basic_Info | B6: Product Specs / Size | C6: Required | D6: Ensure consistent specs for later price records | E6: Text / numeric / date | F6: Fill as instructed
A7: 01_Series_Basic_Info | B7: Release Batch / Version | C7: Required | D7: First edition, reprint, Vol.1, etc. | E7: Text / numeric / date | F7: Fill as instructed
A8: 01_Series_Basic_Info | B8: Official Release Date | C8: Optional | D8: Enter as YYYY-MM-DD | E8: Text / numeric / date | F8: Fill as instructed
A9: 01_Series_Basic_Info | B9: Total Number of Target Characters n | C9: Required | D9: Recommended 6–12; exclude explicitly out-of-scope designs | E9: Text / numeric / date | F9: Fill as instructed
A10: 01_Series_Basic_Info | B10: Official Random Unit Price | C10: Required | D10: Product price only; exclude shipping | E10: Text / numeric / date | F10: Fill as instructed
A11: 01_Series_Basic_Info | B11: Official Purchase Channels | C11: Required | D11: Official site, official store, or other formal channels | E11: Text / numeric / date | F11: Fill as instructed
A12: 01_Series_Basic_Info | B12: Official Shipping Rules | C12: Required | D12: State per-order shipping, combined shipping, or free-shipping rules | E12: Text / numeric / date | F12: Fill as instructed
A13: 01_Series_Basic_Info | B13: Other Official Fees | C13: Optional | D13: Enter 0 if none | E13: Text / numeric / date | F13: Fill as instructed
... A77: 05_Shipping_Transaction_Rules | B77: Transaction Rules Evidence ID | C77: Required | D77: Corresponding screenshot | E77: Text/Numeric | F77: Fill as instructed
